Workbook
Name rngSeasonList: '[1]5. Lists'!$A$2:$A$47
Name Slicer_Base: #N/A
Name Slicer_Divisi: #N/A
Name Slicer_Jabatan: #N/A
Name Slicer_Tipe_Karyawan: #N/A

Sheet Data Karyawan
A1: No ID | B1: Nama Karyawan | C1: Base | D1: Tipe Karyawan | E1: Mulai Bekerja | F1: Agama | G1: Kode Jenis Kelamin | H1: Jenis Kelamin | I1: Tempat | J1: Tanggal Lahir | K1: Usia | L1: KPI Performance | M1: Divisi | N1: Jabatan | O1: Kode Jabatan | P1: Gaji | Q1: Gaji Bonus
A2: N1707 | B2: Dewi Kartini | C2: JAKARTA | D2: Kontrak | E2: 42920 | F2: Kristen | G2: F | H2: =IFERROR(_xlfn.XLOOKUP(G2,'Master Gender'!$B$2:$B$3,'Master Gender'!$A$2:$A$3),"") -> Perempuan | I2: JAKARTA PUSAT | J2: 32089 | K2: =DATEDIF(J2,DATE(2025,12,31),"Y") -> 38 | L2: 0.99 | M2: =IFERROR(_xlfn.XLOOKUP(A2,'Master Position'!$B$2:$B$124,'Master Position'!$A$2:$A$124),"") -> Marketing | N2: =IFERROR(_xlfn.XLOOKUP(A2,'Master Position'!$B$2:$B$124,'Master Position'!$C$2:$C$124),"") -> Senior Staff | O2: =IFERROR(_xlfn.XLOOKUP(N2,'Master Salary'!$B$2:$B$8,'Master Salary'!$A$2:$A$8),"") -> SS | P2: =IFERROR(_xlfn.XLOOKUP(N2,'Master Salary'!$B$2:$B$8,'Master Salary'!$C$2:$C$8),"") -> 5000000 | Q2: =IFERROR(IF(L2>90%,P2*_xlfn.XLOOKUP(N2,'Master Bonus'!$A$3:$A$9,'Master Bonus'!$B$3:$B$9),0),"") -> 5000000
A3: N2498 | B3: Siti Rahayu | C3: JAKARTA | D3: Kontrak | E3: 44417 | F3: Islam | G3: F | H3: =IFERROR(_xlfn.XLOOKUP(G3,'Master Gender'!$B$2:$B$3,'Master Gender'!$A$2:$A$3),"") -> Perempuan | I3: BANDUNG | J3: 33712 | K3: =DATEDIF(J3,DATE(2025,12,31),"Y") -> 33 | L3: 0.77 | M3: =IFERROR(_xlfn.XLOOKUP(A3,'Master Position'!$B$2:$B$124,'Master Position'!$A$2:$A$124),"") -> Marketing | N3: =IFERROR(_xlfn.XLOOKUP(A3,'Master Position'!$B$2:$B$124,'Master Position'!$C$2:$C$124),"") -> Senior Staff | O3: =IFERROR(_xlfn.XLOOKUP(N3,'Master Salary'!$B$2:$B$8,'Master Salary'!$A$2:$A$8),"") -> SS | P3: =IFERROR(_xlfn.XLOOKUP(N3,'Master Salary'!$B$2:$B$8,'Master Salary'!$C$2:$C$8),"") -> 5000000 | Q3: =IFERROR(IF(L3>90%,P3*_xlfn.XLOOKUP(N3,'Master Bonus'!$A$3:$A$9,'Master Bonus'!$B$3:$B$9),0),"") -> 0
A4: E2513 | B4: Lina Puspitasari | C4: JAKARTA | D4: Karyawan Tetap | E4: 44424 | F4: Islam | G4: F | H4: =IFERROR(_xlfn.XLOOKUP(G4,'Master Gender'!$B$2:$B$3,'Master Gender'!$A$2:$A$3),"") -> Perempuan | I4: BOGOR | J4: 34768 | K4: =DATEDIF(J4,DATE(2025,12,31),"Y") -> 30 | L4: 0.7 | M4: =IFERROR(_xlfn.XLOOKUP(A4,'Master Position'!$B$2:$B$124,'Master Position'!$A$2:$A$124),"") -> Marketing | N4: =IFERROR(_xlfn.XLOOKUP(A4,'Master Position'!$B$2:$B$124,'Master Position'!$C$2:$C$124),"") -> Supervisor | O4: =IFERROR(_xlfn.XLOOKUP(N4,'Master Salary'!$B$2:$B$8,'Master Salary'!$A$2:$A$8),"") -> SP | P4: =IFERROR(_xlfn.XLOOKUP(N4,'Master Salary'!$B$2:$B$8,'Master Salary'!$C$2:$C$8),"") -> 7000000 | Q4: =IFERROR(IF(L4>90%,P4*_xlfn.XLOOKUP(N4,'Master Bonus'!$A$3:$A$9,'Master Bonus'!$B$3:$B$9),0),"") -> 0
A5: N1674 | B5: Ratna Kusuma | C5: JAKARTA | D5: Kontrak | E5: 42800 | F5: Islam | G5: F | H5: =IFERROR(_xlfn.XLOOKUP(G5,'Master Gender'!$B$2:$B$3,'Master Gender'!$A$2:$A$3),"") -> Perempuan | I5: JAKARTA | J5: 33569 | K5: =DATEDIF(J5,DATE(2025,12,31),"Y") -> 34 | L5: 0.6 | M5: =IFERROR(_xlfn.XLOOKUP(A5,'Master Position'!$B$2:$B$124,'Master Position'!$A$2:$A$124),"") -> Finance | N5: =IFERROR(_xlfn.XLOOKUP(A5,'Master Position'!$B$2:$B$124,'Master Position'!$C$2:$C$124),"") -> Staff | O5: =IFERROR(_xlfn.XLOOKUP(N5,'Master Salary'!$B$2:$B$8,'Master Salary'!$A$2:$A$8),"") -> ST | P5: =IFERROR(_xlfn.XLOOKUP(N5,'Master Salary'!$B$2:$B$8,'Master Salary'!$C$2:$C$8),"") -> 4000000 | Q5: =IFERROR(IF(L5>90%,P5*_xlfn.XLOOKUP(N5,'Master Bonus'!$A$3:$A$9,'Master Bonus'!$B$3:$B$9),0),"") -> 0
A6: E2640 | B6: Chicco Jerikho | C6: JAKARTA | D6: Karyawan Tetap | E6: 44718 | F6: Kristen | G6: M | H6: =IFERROR(_xlfn.XLOOKUP(G6,'Master Gender'!$B$2:$B$3,'Master Gender'!$A$2:$A$3),"") -> Laki-Laki | I6: LAMPUNG | J6: 35196 | K6: =DATEDIF(J6,DATE(2025,12,31),"Y") -> 29 | L6: 0.7 | M6: =IFERROR(_xlfn.XLOOKUP(A6,'Master Position'!$B$2:$B$124,'Master Position'!$A$2:$A$124),"") -> Finance | N6: =IFERROR(_xlfn.XLOOKUP(A6,'Master Position'!$B$2:$B$124,'Master Position'!$C$2:$C$124),"") -> General Manager | O6: =IFERROR(_xlfn.XLOOKUP(N6,'Master Salary'!$B$2:$B$8,'Master Salary'!$A$2:$A$8),"") -> GM | P6: =IFERROR(_xlfn.XLOOKUP(N6,'Master Salary'!$B$2:$B$8,'Master Salary'!$C$2:$C$8),"") -> 25000000 | Q6: =IFERROR(IF(L6>90%,P6*_xlfn.XLOOKUP(N6,'Master Bonus'!$A$3:$A$9,'Master Bonus'!$B$3:$B$9),0),"") -> 0
A7: N2016 | B7: Arifin Sutedjo | C7: JAKARTA | D7: Kontrak | E7: 43479 | F7: Islam | G7: M | H7: =IFERROR(_xlfn.XLOOKUP(G7,'Master Gender'!$B$2:$B$3,'Master Gender'!$A$2:$A$3),"") -> Laki-Laki | I7: JAKARTA | J7: 34307 | K7: =DATEDIF(J7,DATE(2025,12,31),"Y") -> 32 | L7: 0.67 | M7: =IFERROR(_xlfn.XLOOKUP(A7,'Master Position'!$B$2:$B$124,'Master Position'!$A$2:$A$124),"") -> Finance | N7: =IFERROR(_xlfn.XLOOKUP(A7,'Master Position'!$B$2:$B$124,'Master Position'!$C$2:$C$124),"") -> Staff | O7: =IFERROR(_xlfn.XLOOKUP(N7,'Master Salary'!$B$2:$B$8,'Master Salary'!$A$2:$A$8),"") -> ST | P7: =IFERROR(_xlfn.XLOOKUP(N7,'Master Salary'!$B$2:$B$8,'Master Salary'!$C$2:$C$8),"") -> 4000000 | Q7: =IFERROR(IF(L7>90%,P7*_xlfn.XLOOKUP(N7,'Master Bonus'!$A$3:$A$9,'Master Bonus'!$B$3:$B$9),0),"") -> 0
A8: E2054 | B8: Agus Suharto | C8: JAKARTA | D8: Karyawan Tetap | E8: 43577 | F8: Islam | G8: M | H8: =IFERROR(_xlfn.XLOOKUP(G8,'Master Gender'!$B$2:$B$3,'Master Gender'!$A$2:$A$3),"") -> Laki-Laki | I8: PURBALINGGA | J8: 34600 | K8: =DATEDIF(J8,DATE(2025,12,31),"Y") -> 31 | L8: 0.63 | M8: =IFERROR(_xlfn.XLOOKUP(A8,'Master Position'!$B$2:$B$124,'Master Position'!$A$2:$A$124),"") -> Finance | N8: =IFERROR(_xlfn.XLOOKUP(A8,'Master Position'!$B$2:$B$124,'Master Position'!$C$2:$C$124),"") -> Senior Manager | O8: =IFERROR(_xlfn.XLOOKUP(N8,'Master Salary'!$B$2:$B$8,'Master Salary'!$A$2:$A$8),"") -> SM | P8: =IFERROR(_xlfn.XLOOKUP(N8,'Master Salary'!$B$2:$B$8,'Master Salary'!$C$2:$C$8),"") -> 18000000 | Q8: =IFERROR(IF(L8>90%,P8*_xlfn.XLOOKUP(N8,'Master Bonus'!$A$3:$A$9,'Master Bonus'!$B$3:$B$9),0),"") -> 0
A9: E1881 | B9: Lita Damayanti | C9: JAKARTA | D9: Karyawan Tetap | E9: 43276 | F9: Islam | G9: F | H9: =IFERROR(_xlfn.XLOOKUP(G9,'Master Gender'!$B$2:$B$3,'Master Gender'!$A$2:$A$3),"") -> Perempuan | I9: TANGERANG | J9: 34317 | K9: =DATEDIF(J9,DATE(2025,12,31),"Y") -> 32 | L9: 0.79 | M9: =IFERROR(_xlfn.XLOOKUP(A9,'Master Position'!$B$2:$B$124,'Master Position'!$A$2:$A$124),"") -> Finance | N9: =IFERROR(_xlfn.XLOOKUP(A9,'Master Position'!$B$2:$B$124,'Master Position'!$C$2:$C$124),"") -> Staff | O9: =IFERROR(_xlfn.XLOOKUP(N9,'Master Salary'!$B$2:$B$8,'Master Salary'!$A$2:$A$8),"") -> ST | P9: =IFERROR(_xlfn.XLOOKUP(N9,'Master Salary'!$B$2:$B$8,'Master Salary'!$C$2:$C$8),"") -> 4000000 | Q9: =IFERROR(IF(L9>90%,P9*_xlfn.XLOOKUP(N9,'Master Bonus'!$A$3:$A$9,'Master Bonus'!$B$3:$B$9),0),"") -> 0
A10: E2161 | B10: Eko Pramono | C10: JAKARTA | D10: Karyawan Tetap | E10: 43801 | F10: Islam | G10: M | H10: =IFERROR(_xlfn.XLOOKUP(G10,'Master Gender'!$B$2:$B$3,'Master Gender'!$A$2:$A$3),"") -> Laki-Laki | I10: JAKARTA | J10: 34428 | K10: =DATEDIF(J10,DATE(2025,12,31),"Y") -> 31 | L10: 0.94 | M10: =IFERROR(_xlfn.XLOOKUP(A10,'Master Position'!$B$2:$B$124,'Master Position'!$A$2:$A$124),"") -> Marketing | N10: =IFERROR(_xlfn.XLOOKUP(A10,'Master Position'!$B$2:$B$124,'Master Position'!$C$2:$C$124),"") -> Senior Manager | O10: =IFERROR(_xlfn.XLOOKUP(N10,'Master Salary'!$B$2:$B$8,'Master Salary'!$A$2:$A$8),"") -> SM | P10: =IFERROR(_xlfn.XLOOKUP(N10,'Master Salary'!$B$2:$B$8,'Master Salary'!$C$2:$C$8),"") -> 18000000 | Q10: =IFERROR(IF(L10>90%,P10*_xlfn.XLOOKUP(N10,'Master Bonus'!$A$3:$A$9,'Master Bonus'!$B$3:$B$9),0),"") -> 36000000
A11: N2031 | B11: Lina Handayani | C11: JAKARTA | D11: Kontrak | E11: 43528 | F11: Islam | G11: F | H11: =IFERROR(_xlfn.XLOOKUP(G11,'Master Gender'!$B$2:$B$3,'Master Gender'!$A$2:$A$3),"") -> Perempuan | I11: BANDUNG | J11: 33189 | K11: =DATEDIF(J11,DATE(2025,12,31),"Y") -> 35 | L11: 0.62 | M11: =IFERROR(_xlfn.XLOOKUP(A11,'Master Position'!$B$2:$B$124,'Master Position'!$A$2:$A$124),"") -> Production | N11: =IFERROR(_xlfn.XLOOKUP(A11,'Master Position'!$B$2:$B$124,'Master Position'!$C$2:$C$124),"") -> Staff | O11: =IFERROR(_xlfn.XLOOKUP(N11,'Master Salary'!$B$2:$B$8,'Master Salary'!$A$2:$A$8),"") -> ST | P11: =IFERROR(_xlfn.XLOOKUP(N11,'Master Salary'!$B$2:$B$8,'Master Salary'!$C$2:$C$8),"") -> 4000000 | Q11: =IFERROR(IF(L11>90%,P11*_xlfn.XLOOKUP(N11,'Master Bonus'!$A$3:$A$9,'Master Bonus'!$B$3:$B$9),0),"") -> 0
A12: N1173 | B12: Chicco Kurniawan | C12: JAKARTA | D12: Kontrak | E12: 41792 | F12: Islam | G12: M | H12: =IFERROR(_xlfn.XLOOKUP(G12,'Master Gender'!$B$2:$B$3,'Master Gender'!$A$2:$A$3),"") -> Laki-Laki | I12: JAKARTA | J12: 32950 | K12: =DATEDIF(J12,DATE(2025,12,31),"Y") -> 35 | L12: 0.69 | M12: =IFERROR(_xlfn.XLOOKUP(A12,'Master Position'!$B$2:$B$124,'Master Position'!$A$2:$A$124),"") -> Sales | N12: =IFERROR(_xlfn.XLOOKUP(A12,'Master Position'!$B$2:$B$124,'Master Position'!$C$2:$C$124),"") -> Staff | O12: =IFERROR(_xlfn.XLOOKUP(N12,'Master Salary'!$B$2:$B$8,'Master Salary'!$A$2:$A$8),"") -> ST | P12: =IFERROR(_xlfn.XLOOKUP(N12,'Master Salary'!$B$2:$B$8,'Master Salary'!$C$2:$C$8),"") -> 4000000 | Q12: =IFERROR(IF(L12>90%,P12*_xlfn.XLOOKUP(N12,'Master Bonus'!$A$3:$A$9,'Master Bonus'!$B$3:$B$9),0),"") -> 0
A13: E1005 | B13: Yanto Setiawan | C13: JAKARTA | D13: Karyawan Tetap | E13: 39295 | F13: Islam | G13: M | H13: =IFERROR(_xlfn.XLOOKUP(G13,'Master Gender'!$B$2:$B$3,'Master Gender'!$A$2:$A$3),"") -> Laki-Laki | I13: TASIKMALAYA | J13: 28916 | K13: =DATEDIF(J13,DATE(2025,12,31),"Y") -> 46 | L13: 0.84 | M13: =IFERROR(_xlfn.XLOOKUP(A13,'Master Position'!$B$2:$B$124,'Master Position'!$A$2:$A$124),"") -> Human Resources | N13: =IFERROR(_xlfn.XLOOKUP(A13,'Master Position'!$B$2:$B$124,'Master Position'!$C$2:$C$124),"") -> Senior Staff | O13: =IFERROR(_xlfn.XLOOKUP(N13,'Master Salary'!$B$2:$B$8,'Master Salary'!$A$2:$A$8),"") -> SS | P13: =IFERROR(_xlfn.XLOOKUP(N13,'Master Salary'!$B$2:$B$8,'Master Salary'!$C$2:$C$8),"") -> 5000000 | Q13: =IFERROR(IF(L13>90%,P13*_xlfn.XLOOKUP(N13,'Master Bonus'!$A$3:$A$9,'Master Bonus'!$B$3:$B$9),0),"") -> 0
... A124: N1713 | B124: Sari Winarno | C124: JAKARTA | D124: Kontrak | E124: 42926 | F124: Islam | G124: F | H124: =IFERROR(_xlfn.XLOOKUP(G124,'Master Gender'!$B$2:$B$3,'Master Gender'!$A$2:$A$3),"") -> Perempuan | I124: JAKARTA | J124: 31467 | K124: =DATEDIF(J124,DATE(2025,12,31),"Y") -> 39 | L124: 0.61 | M124: =IFERROR(_xlfn.XLOOKUP(A124,'Master Position'!$B$2:$B$124,'Master Position'!$A$2:$A$124),"") -> Account Manager | N124: =IFERROR(_xlfn.XLOOKUP(A124,'Master Position'!$B$2:$B$124,'Master Position'!$C$2:$C$124),"") -> Staff | O124: =IFERROR(_xlfn.XLOOKUP(N124,'Master Salary'!$B$2:$B$8,'Master Salary'!$A$2:$A$8),"") -> ST | P124: =IFERROR(_xlfn.XLOOKUP(N124,'Master Salary'!$B$2:$B$8,'Master Salary'!$C$2:$C$8),"") -> 4000000 | Q124: =IFERROR(IF(L124>90%,P124*_xlfn.XLOOKUP(N124,'Master Bonus'!$A$3:$A$9,'Master Bonus'!$B$3:$B$9),0),"") -> 0

Sheet Master Position
A1: Divisi | B1: No ID | C1: Jabatan
A2: Marketing | B2: N1707 | C2: Senior Staff
A3: Marketing | B3: N2498 | C3: Senior Staff
A4: Marketing | B4: E2513 | C4: Supervisor
A5: Finance | B5: N1674 | C5: Staff
A6: Finance | B6: E2640 | C6: General Manager
A7: Finance | B7: N2016 | C7: Staff
A8: Finance | B8: E2054 | C8: Senior Manager
A9: Finance | B9: E1881 | C9: Staff
A10: Marketing | B10: E2161 | C10: Senior Manager
A11: Production | B11: N2031 | C11: Staff
A12: Sales | B12: N1173 | C12: Staff
... A124: Account Manager | B124: N1713 | C124: Staff

Sheet Master Gender
A1: Jenis Kelamin | B1: Kode
A2: Perempuan | B2: F
A3: Laki-Laki | B3: M

Sheet Master Salary
A1: Kode Jabatan | B1: Jabatan | C1: Gaji
A2: CE | B2: CEO | C2: 40000000
A3: GM | B3: General Manager | C3: 25000000
A4: SM | B4: Senior Manager | C4: 18000000
A5: JM | B5: Junior Manager | C5: 12000000
A6: SP | B6: Supervisor | C6: 7000000
A7: SS | B7: Senior Staff | C7: 5000000
A8: ST | B8: Staff | C8: 4000000

Sheet Master Bonus
B1: Syarat KPI >90%
A2: Jabatan | B2: Pengali Gaji Bonus
A3: CEO | B3: 2
A4: General Manager | B4: 2
A5: Senior Manager | B5: 2
A6: Junior Manager | B6: 2
A7: Supervisor | B7: 1
A8: Senior Staff | B8: 1
A9: Staff | B9: 1

Sheet Helper
A1: Count of Nama Karyawan | C1: Row Labels | D1: Count of Nama Karyawan | F1: Row Labels | G1: Count of Nama Karyawan
A2: 123 | C2: CEO | D2: 1 | F2: JAKARTA | G2: 109
C3: Junior Manager | D3: 6 | F3: MEDAN | G3: 4
C4: Senior Manager | D4: 10 | F4: BANDUNG | G4: 4
A5: Average of Usia | C5: General Manager | D5: 11 | F5: SURABAYA | G5: 3
A6: 36.609756 | C6: Supervisor | D6: 28 | F6: MALANG | G6: 2
C7: Staff | D7: 32 | F7: DENPASAR | G7: 1
C8: Senior Staff | D8: 35 | F8: Grand Total | G8: 123
A9: Average of KPI Performance | C9: Grand Total | D9: 123
A10: 0.78300813
F11: Row Labels | G11: Sum of Gaji Pokok
C12: Row Labels | D12: Count of Nama Karyawan | F12: General Manager | G12: 275000000
A13: Sum of Total Gaji (Gaji Pokok & Bonus) | C13: Executive | D13: 2 | F13: Supervisor | G13: 196000000
A14: 1267000000 | C14: Customer Service | D14: 2 | F14: Senior Manager | G14: 180000000
C15: Data | D15: 6 | F15: Senior Staff | G15: 175000000
C16: Procurement | D16: 6 | F16: Staff | G16: 128000000
C17: IT | D17: 6 | F17: Junior Manager | G17: 72000000
C18: Sales | D18: 7 | F18: CEO | G18: 40000000
C19: Account Manager | D19: 14 | F19: Grand Total | G19: 1066000000
C20: Human Resources | D20: 15
C21: Production | D21: 20
C22: Marketing | D22: 21 | F22: Row Labels | G22: Sum of Gaji Bonus
C23: Finance | D23: 24 | F23: Senior Manager | G23: 108000000
C24: Grand Total | D24: 123 | F24: Supervisor | G24: 49000000
F25: Senior Staff | G25: 40000000
F26: Staff | G26: 4000000
B27: Row Labels | C27: Count of Nama Karyawan | D27: Count of Nama Karyawan (Cumulative) | F27: Junior Manager | G27: 0
B28: 2000 | C28: 4 | D28: 4 | F28: General Manager | G28: 0
B29: 2002 | C29: 1 | D29: 5 | F29: CEO | G29: 0
B30: 2004 | C30: 2 | D30: 7 | F30: Grand Total | G30: 201000000
B31: 2005 | C31: 1 | D31: 8
B32: 2006 | C32: 5 | D32: 13
B33: 2007 | C33: 2 | D33: 15 | F33: Row Labels | G33: Count of Nama Karyawan
B34: 2008 | C34: 3 | D34: 18 | F34: Laki-Laki | G34: 67
B35: 2009 | C35: 1 | D35: 19 | F35: Perempuan | G35: 56
B36: 2010 | C36: 4 | D36: 23 | F36: Grand Total | G36: 123
B37: 2011 | C37: 1 | D37: 24
B38: 2012 | C38: 3 | D38: 27
B39: 2013 | C39: 2 | D39: 29
B40: 2014 | C40: 4 | D40: 33
...

Sheet Dashboard
C1: Employee & Workforce Monitoring Dashboard
D3: Employee Data
D5: No ID | E5: E1064 | G5: Jenis Kelamin | H5: =_xlfn.XLOOKUP($E$5,'Data Karyawan'!$A$2:$A$124,'Data Karyawan'!$H$2:$H$124) -> Laki-Laki | J5: Base | K5: =_xlfn.XLOOKUP($E$5,'Data Karyawan'!$A$2:$A$124,'Data Karyawan'!$C$2:$C$124) -> JAKARTA | M5: Gaji | N5: {=_xlfn.XLOOKUP($E$5,'Data Karyawan'!$A$2:$A$124,'Data Karyawan'!$P$2:PH$124)} -> 18000000 | O5: 36000000 | P5: 0 | Q5: 0 | R5: 0 | S5: 0 | T5: 0 | U5: 0 | V5: 0 | W5: 0 | X5: 0 | Y5: 0 | Z5: 0 | AA5: 0 | AB5: 0 | AC5: 0 | AD5: 0 | AE5: 0 | AF5: 0 | AG5: 0 | AH5: 0 | AI5: 0 | AJ5: 0 | AK5: 0 | AL5: 0 | AM5: 0 | AN5: 0 | AO5: 0 | AP5: 0 | AQ5: 0 | AR5: 0 | AS5: 0 | AT5: 0 | AU5: 0 | AV5: 0 | AW5: 0 | AX5: 0 | AY5: 0 | AZ5: 0 | BA5: 0 | BB5: 0 | BC5: 0 | BD5: 0 | BE5: 0 | BF5: 0 | BG5: 0 | BH5: 0 | BI5: 0 | BJ5: 0 | BK5: 0 | BL5: 0 | BM5: 0 | BN5: 0 | BO5: 0 | BP5: 0 | BQ5: 0 | BR5: 0 | BS5: 0 | BT5: 0 | BU5: 0 | BV5: 0 | BW5: 0 | BX5: 0 | BY5: 0 | BZ5: 0 | CA5: 0 | CB5: 0 | CC5: 0 | CD5: 0 | CE5: 0 | CF5: 0 | CG5: 0 | CH5: 0 | CI5: 0 | CJ5: 0 | CK5: 0 | CL5: 0 | CM5: 0 | CN5: 0 | CO5: 0 | CP5: 0 | CQ5: 0 | CR5: 0 | CS5: 0 | CT5: 0 | CU5: 0 | CV5: 0 | CW5: 0 | CX5: 0 | CY5: 0 | CZ5: 0 | DA5: 0 | DB5: 0 | DC5: 0 | DD5: 0 | DE5: 0 | DF5: 0 | DG5: 0 | DH5: 0 | DI5: 0 | DJ5: 0 | DK5: 0 | DL5: 0 | DM5: 0 | DN5: 0 | DO5: 0 | DP5: 0 | DQ5: 0 | DR5: 0 | DS5: 0 | DT5: 0 | DU5: 0 | DV5: 0 | DW5: 0 | DX5: 0 | DY5: 0 | DZ5: 0 | EA5: 0 | EB5: 0 | EC5: 0 | ED5: 0 | EE5: 0 | EF5: 0 | EG5: 0 | EH5: 0 | EI5: 0 | EJ5: 0 | EK5: 0 | EL5: 0 | EM5: 0 | EN5: 0 | EO5: 0 | EP5: 0 | EQ5: 0 | ER5: 0 | ES5: 0 | ET5: 0 | EU5: 0 | EV5: 0 | EW5: 0 | EX5: 0 | EY5: 0 | EZ5: 0 | FA5: 0 | FB5: 0 | FC5: 0 | FD5: 0 | FE5: 0 | FF5: 0 | FG5: 0 | FH5: 0 | FI5: 0 | FJ5: 0 | FK5: 0 | FL5: 0 | FM5: 0 | FN5: 0 | FO5: 0 | FP5: 0 | FQ5: 0 | FR5: 0 | FS5: 0 | FT5: 0 | FU5: 0 | FV5: 0 | FW5: 0 | FX5: 0 | FY5: 0 | FZ5: 0 | GA5: 0 | GB5: 0 | GC5: 0 | GD5: 0 | GE5: 0 | GF5: 0 | GG5: 0 | GH5: 0 | GI5: 0 | GJ5: 0 | GK5: 0 | GL5: 0 | GM5: 0 | GN5: 0 | GO5: 0 | GP5: 0 | GQ5: 0 | GR5: 0 | GS5: 0 | GT5: 0 | GU5: 0 | GV5: 0 | GW5: 0 | GX5: 0 | GY5: 0 | GZ5: 0 | HA5: 0 | HB5: 0 | HC5: 0 | HD5: 0 | HE5: 0 | HF5: 0 | HG5: 0 | HH5: 0 | HI5: 0 | HJ5: 0 | HK5: 0 | HL5: 0 | HM5: 0 | HN5: 0 | HO5: 0 | HP5: 0 | HQ5: 0 | HR5: 0 | HS5: 0 | HT5: 0 | HU5: 0 | HV5: 0 | HW5: 0 | HX5: 0 | HY5: 0 | HZ5: 0 | IA5: 0 | IB5: 0 | IC5: 0 | ID5: 0 | IE5: 0 | IF5: 0 | IG5: 0 | IH5: 0 | II5: 0 | IJ5: 0 | IK5: 0 | IL5: 0 | IM5: 0 | IN5: 0 | IO5: 0 | IP5: 0 | IQ5: 0 | IR5: 0 | IS5: 0 | IT5: 0 | IU5: 0 | IV5: 0 | IW5: 0 | IX5: 0 | IY5: 0 | IZ5: 0 | JA5: 0 | JB5: 0 | JC5: 0 | JD5: 0 | JE5: 0 | JF5: 0 | JG5: 0 | JH5: 0 | JI5: 0 | JJ5: 0 | JK5: 0 | JL5: 0 | JM5: 0 | JN5: 0 | JO5: 0 | JP5: 0 | JQ5: 0 | JR5: 0 | JS5: 0 | JT5: 0 | JU5: 0 | JV5: 0 | JW5: 0 | JX5: 0 | JY5: 0 | JZ5: 0 | KA5: 0 | KB5: 0 | KC5: 0 | KD5: 0 | KE5: 0 | KF5: 0 | KG5: 0 | KH5: 0 | KI5: 0 | KJ5: 0 | KK5: 0 | KL5: 0 | KM5: 0 | KN5: 0 | KO5: 0 | KP5: 0 | KQ5: 0 | KR5: 0 | KS5: 0 | KT5: 0 | KU5: 0 | KV5: 0 | KW5: 0 | KX5: 0 | KY5: 0 | KZ5: 0 | LA5: 0 | LB5: 0 | LC5: 0 | LD5: 0 | LE5: 0 | LF5: 0 | LG5: 0 | LH5: 0 | LI5: 0 | LJ5: 0 | LK5: 0 | LL5: 0 | LM5: 0 | LN5: 0 | LO5: 0 | LP5: 0 | LQ5: 0 | LR5: 0 | LS5: 0 | LT5: 0 | LU5: 0 | LV5: 0 | LW5: 0 | LX5: 0 | LY5: 0 | LZ5: 0 | MA5: 0 | MB5: 0 | MC5: 0 | MD5: 0 | ME5: 0 | MF5: 0 | MG5: 0 | MH5: 0 | MI5: 0 | MJ5: 0 | MK5: 0 | ML5: 0 | MM5: 0 | MN5: 0 | MO5: 0 | MP5: 0 | MQ5: 0 | MR5: 0 | MS5: 0 | MT5: 0 | MU5: 0 | MV5: 0 | MW5: 0 | MX5: 0 | MY5: 0 | MZ5: 0 | NA5: 0 | NB5: 0 | NC5: 0 | ND5: 0 | NE5: 0 | NF5: 0 | NG5: 0 | NH5: 0 | NI5: 0 | NJ5: 0 | NK5: 0 | NL5: 0 | NM5: 0 | NN5: 0 | NO5: 0 | NP5: 0 | NQ5: 0 | NR5: 0 | NS5: 0 | NT5: 0 | NU5: 0 | NV5: 0 | NW5: 0 | NX5: 0 | NY5: 0 | NZ5: 0 | OA5: 0 | OB5: 0 | OC5: 0 | OD5: 0 | OE5: 0 | OF5: 0 | OG5: 0 | OH5: 0 | OI5: 0 | OJ5: 0 | OK5: 0 | OL5: 0 | OM5: 0 | ON5: 0 | OO5: 0 | OP5: 0 | OQ5: 0 | OR5: 0 | OS5: 0 | OT5: 0 | OU5: 0 | OV5: 0 | OW5: 0 | OX5: 0 | OY5: 0 | OZ5: 0 | PA5: 0 | PB5: 0 | PC5: 0 | PD5: 0 | PE5: 0 | PF5: 0
D7: Nama | E7: =_xlfn.XLOOKUP($E$5,'Data Karyawan'!$A$2:$A$124,'Data Karyawan'!$B$2:$B$124) -> Budi Santoso | G7: Tipe Karyawan | H7: =_xlfn.XLOOKUP($E$5,'Data Karyawan'!$A$2:$A$124,'Data Karyawan'!$D$2:$D$124) -> Karyawan Tetap | J7: Divisi | K7: =_xlfn.XLOOKUP($E$5,'Data Karyawan'!$A$2:$A$124,'Data Karyawan'!$M$2:$M$124) -> Human Resources | M7: Performa KPI | N7: =_xlfn.XLOOKUP($E$5,'Data Karyawan'!$A$2:$A$124,'Data Karyawan'!$L$2:$L$124) -> 0.97
D9: Usia | E9: =_xlfn.XLOOKUP($E$5,'Data Karyawan'!$A$2:$A$124,'Data Karyawan'!$K$2:$K$124) -> 41 | G9: Mulai Bekerja | H9: =_xlfn.XLOOKUP($E$5,'Data Karyawan'!$A$2:$A$124,'Data Karyawan'!$E$2:$E$124) -> 40452 | J9: Jabatan | K9: =_xlfn.XLOOKUP($E$5,'Data Karyawan'!$A$2:$A$124,'Data Karyawan'!$N$2:$N$124) -> Senior Manager | M9: Gaji Bonus | N9: =_xlfn.XLOOKUP($E$5,'Data Karyawan'!$A$2:$A$124,'Data Karyawan'!$Q$2:$Q$124) -> 36000000
D12: Total Karyawan by Jabatan | G12: Total Karyawan by Divisi | J12: Tren Jumlah Karyawan by Year
D28: Total Karyawan by Base | G28: Total Gaji Pokok by Jabatan | J28: Total Gaji Bonus by Jabatan | M28: Distribusi Karyawan by Jenis Kelamin
